Traceback (most recent call last):
  File "/usr/local/bin/certbot", line 11, in <module>
    load_entry_point('certbot==0.11.1', 'console_scripts', 'certbot')()
  File "/usr/local/Cellar/certbot/0.11.1/libexec/lib/python2.7/site-packages/certbot/main.py", line 865, in main
    make_or_verify_needed_dirs(config)
  File "/usr/local/Cellar/certbot/0.11.1/libexec/lib/python2.7/site-packages/certbot/main.py", line 819, in make_or_verify_needed_dirs
    os.geteuid(), config.strict_permissions)
  File "/usr/local/Cellar/certbot/0.11.1/libexec/lib/python2.7/site-packages/certbot/main.py", line 814, in make_or_verify_core_dir
    raise errors.Error(_PERM_ERR_FMT.format(error))
Error: The following error was encountered:
[Errno 13] Permission denied: '/etc/letsencrypt'
If running as non-root, set --config-dir, --work-dir, and --logs-dir to writeable paths.
